Workbook

Sheet BESS
B2: 2026 BESS in operation MW | G2: 2026 BESS in operation MWh | L2: 2026 BESS in test MW | R2: 2026 BESS in test MWh | W2: 2026 BESS in construction MW | AC2: 2026 BESS in construction MWh
C3: Generadoras | D3: Min. Energía | E3: ACERA | H3: E. Abierta | I3: Generadoras | J3: ACERA | M3: Generadoras | N3: Min. Energía | O3: Coordinador | P3: ACERA | S3: Generadoras | T3: ACERA | X3: E. Abierta | Y3: Generadoras | Z3: Min. Energía | AA3: ACERA | AD3: Generadoras | AE3: ACERA
B4: January | C4: 2159 | D4: 1584 | E4: 1575 | G4: January | H4: =2+50+250+1812+1704+1100 -> 4918 | I4: 8662 | J4: 6384 | L4: January | M4: 1065 | N4: 1601 | O4: =1914.9*0.2 -> 382.98 | P4: 746 | R4: January | S4: 4900 | T4: 2688 | W4: January | X4: 7253 | Y4: 6731 | Z4: 5783 | AA4: 7278 | AC4: January | AD4: 30374 | AE4: 32504
B5: February | C5: 2480 | D5: 1700 | E5: 1691 | G5: February | H5: =2+250+900+621+5240 -> 7013 | I5: 8174 | J5: 6964 | L5: February | M5: 988 | N5: 1531 | O5: =2471.3*0.292 -> 721.6196 | P5: 1486 | R5: February | S5: 3381 | T5: 5972 | W5: February | X5: 6571 | Y5: 6660 | Z5: 6179 | AA5: 6596 | AC5: February | AD5: 23327 | AE5: 29473
B6: March | C6: 2529 | D6: 2071 | E6: 1691 | G6: March | H6: =2+250+621+5240+55 -> 6168 | I6: 8786 | J6: 6964 | L6: March | M6: 1255 | N6: 2119 | O6: =2883*0.418 -> 1205.094 | P6: 1832 | R6: March | S6: 3699 | T6: 7102 | W6: March | X6: 6358 | Y6: 6361 | Z6: 5646 | AA6: 6385 | AC6: March | AD6: 22479 | AE6: 29018
B7: April | C7: 3293 | D7: 2071 | E7: 2063 | G7: April | I7: 13174 | J7: 8477 | L7: April | M7: 1301 | N7: 2225 | O7: =2720.4*0.444 -> 1207.8576 | P7: 2124 | R7: April | S7: 4163 | T7: 9730 | W7: April | Y7: 5684 | Z7: 5799 | AA7: 5977 | AC7: April | AD7: 24929 | AE7: 25896
B8: May | C8: 3293 | D8: 2071 | E8: 2063 | G8: May | H8: 3898 | I8: 15271 | J8: 8777 | L8: May | M8: 1709 | N8: 2524 | O8: =3031.8*0.553 -> 1676.5854 | P8: 2425 | R8: May | S8: 7297 | T8: 11275 | W8: May | X8: 5728 | Y8: 5554 | Z8: 5639 | AA8: 5746 | AC8: May | AD8: 24061 | AE8: 24638
B9: June | D9: 2291 | E9: 2318 | G9: June | J9: 10057 | L9: June | N9: 2760 | O9: =3176.9*0.489 -> 1553.5041 | P9: 2958 | R9: June | T9: 13593 | W9: June | X9: 5219 | Z9: =+(4705+505) -> 5210 | AA9: 4987 | AC9: June | AE9: 21175
B10: July | D10: 2625 | E10: 2655 | G10: July | J10: 11250 | L10: July | N10: 3183 | O10: =2357.2*0.56 -> 1320.032 | P10: 3151 | R10: July | T10: 14698 | W10: July | X10: 4972 | Z10: =+(4268+705) -> 4973 | AA10: 5040 | AC10: July | AE10: 21721
B11: August | D11: 3123 | E11: 3116 | G11: August | J11: 13522 | L11: August | N11: 2686 | P11: 2686 | R11: August | T11: 12408 | W11: August | X11: 5149 | AA11: 5217 | AC11: August | AE11: 22330
B12: September | G12: September | L12: September | R12: September | W12: September | AC12: September
B13: October | G13: October | L13: October | R13: October | W13: October | AC13: October
B14: November | G14: November | L14: November | R14: November | W14: November | AC14: November
B15: December | G15: December | L15: December | R15: December | W15: December | AC15: December
A17: Evolución capacidad BESS según fecha estimada de interconexión (Updated September 2026 — E. Abierta, Res. Ex. 475, datos al 31-ago-2026)
A18: Month | B18: Year | C18: Acumulado | D18: Mensual
A19: 45962 | B19: 2025 | C19: 0 | D19: 0
A20: 45992 | B20: 2025 | C20: =+C19+D19 -> 0 | D20: 261
A21: 46023 | B21: 2026 | C21: =+C20+D20 -> 261 | D21: 0
A22: 46054 | B22: 2026 | C22: =+C21+D21 -> 261 | D22: 40
A23: 46082 | B23: 2026 | C23: =+C22+D22 -> 301 | D23: 0
A24: 46113 | B24: 2026 | C24: =+C23+D23 -> 301 | D24: 0
A25: 46143 | B25: 2026 | C25: =+C24+D24 -> 301 | D25: 0
A26: 46174 | B26: 2026 | C26: =+C25+D25 -> 301 | D26: 912
A27: 46204 | B27: 2026 | C27: =+C26+D26 -> 1213 | D27: 255
A28: 46235 | B28: 2026 | C28: =+C27+D27 -> 1468 | D28: 1617
A29: 46266 | B29: 2026 | C29: =+C28+D28 -> 3085 | D29: 1400
A30: 46296 | B30: 2026 | C30: =+C29+D29 -> 4485 | D30: 2937
A31: 46327 | B31: 2026 | C31: =+C30+D30 -> 7422 | D31: 107
... A57: 47150 | B57: 2029 | C57: =+C56+D56 -> 21844 | D57: 162
A60: BESS Situation in Chile (ACERA, 2026)
B61: Operation | D61: Test | F61: Construction
A62: Month | B62: MW | C62: MWh | D62: MW | E62: MWh | F62: MW | G62: MWh
A63: January | B63: =IF(BESS!E4="","",BESS!E4) -> 1575 | C63: =IF(BESS!J4="","",BESS!J4) -> 6384 | D63: =IF(BESS!P4="","",BESS!P4) -> 746 | E63: =IF(BESS!T4="","",BESS!T4) -> 2688 | F63: =IF(BESS!AA4="","",BESS!AA4) -> 7278 | G63: =IF(BESS!AE4="","",BESS!AE4) -> 32504
A64: February | B64: =IF(BESS!E5="","",BESS!E5) -> 1691 | C64: =IF(BESS!J5="","",BESS!J5) -> 6964 | D64: =IF(BESS!P5="","",BESS!P5) -> 1486 | E64: =IF(BESS!T5="","",BESS!T5) -> 5972 | F64: =IF(BESS!AA5="","",BESS!AA5) -> 6596 | G64: =IF(BESS!AE5="","",BESS!AE5) -> 29473
A65: March | B65: =IF(BESS!E6="","",BESS!E6) -> 1691 | C65: =IF(BESS!J6="","",BESS!J6) -> 6964 | D65: =IF(BESS!P6="","",BESS!P6) -> 1832 | E65: =IF(BESS!T6="","",BESS!T6) -> 7102 | F65: =IF(BESS!AA6="","",BESS!AA6) -> 6385 | G65: =IF(BESS!AE6="","",BESS!AE6) -> 29018
A66: April | B66: =IF(BESS!E7="","",BESS!E7) -> 2063 | C66: =IF(BESS!J7="","",BESS!J7) -> 8477 | D66: =IF(BESS!P7="","",BESS!P7) -> 2124 | E66: =IF(BESS!T7="","",BESS!T7) -> 9730 | F66: =IF(BESS!AA7="","",BESS!AA7) -> 5977 | G66: =IF(BESS!AE7="","",BESS!AE7) -> 25896
A67: May | B67: =IF(BESS!E8="","",BESS!E8) -> 2063 | C67: =IF(BESS!J8="","",BESS!J8) -> 8777 | D67: =IF(BESS!P8="","",BESS!P8) -> 2425 | E67: =IF(BESS!T8="","",BESS!T8) -> 11275 | F67: =IF(BESS!AA8="","",BESS!AA8) -> 5746 | G67: =IF(BESS!AE8="","",BESS!AE8) -> 24638
A68: June | B68: =IF(BESS!E9="","",BESS!E9) -> 2318 | C68: =IF(BESS!J9="","",BESS!J9) -> 10057 | D68: =IF(BESS!P9="","",BESS!P9) -> 2958 | E68: =IF(BESS!T9="","",BESS!T9) -> 13593 | F68: =IF(BESS!AA9="","",BESS!AA9) -> 4987 | G68: =IF(BESS!AE9="","",BESS!AE9) -> 21175
A69: July | B69: =IF(BESS!E10="","",BESS!E10) -> 2655 | C69: =IF(BESS!J10="","",BESS!J10) -> 11250 | D69: =IF(BESS!P10="","",BESS!P10) -> 3151 | E69: =IF(BESS!T10="","",BESS!T10) -> 14698 | F69: =IF(BESS!AA10="","",BESS!AA10) -> 5040 | G69: =IF(BESS!AE10="","",BESS!AE10) -> 21721
...

Sheet Energy Matrix
B2: January | C2: February | D2: March | E2: April | F2: May | G2: June | H2: July
A3: Reservoir Hydraulics | B3: 3514.7 | C3: 4184.7 | D3: 4184.7 | E3: 4184.7 | F3: 4184.7 | G3: 4167.7 | H3: 4167.7
A4: Run if the River Hydraulics | B4: 4034.9 | C4: 3368 | D4: 3368 | E4: 3368 | F4: 3369.9 | G4: 3386.9 | H4: 3388.5
A5: Natural Gas | B5: 5643.1 | C5: 5300 | D5: 5384.5 | E5: 5384.5 | F5: 5384.5 | G5: 5384.5 | H5: 4859.72
A6: Coal | B6: 2804.3 | C6: 3181.2 | D6: 3138.2 | E6: 3138.2 | F6: 3138.2 | G6: 3138.2 | H6: 3138.25
A7: Diesel | B7: 3096.2 | C7: 3053.8 | D7: 3075.4 | E7: 3083.6 | F7: 3083.6 | G7: 3086.6 | H7: 3105.08
A8: Other thermal | B8: 908.6 | C8: 908.6 | D8: 908.6 | E8: 908.6 | F8: 908.6 | G8: 908.6 | H8: 1392.1
A9: Eolic | B9: 6348.8 | C9: 6348.8 | D9: 6352.2 | E9: 6352.2 | F9: 6658.2 | G9: 6910.4 | H9: 6837.11
A10: Sola (Thermal) | B10: 114.4 | C10: 114.4 | D10: 114.4 | E10: 114.4 | F10: 114.4 | G10: 114.4 | H10: 114.4
A11: Solar (PV) | B11: 12546.5 | C11: 12836.7 | D11: 13026.4 | E11: 13227.9 | F11: 13268.1 | G11: 13556.4 | H11: 14049.4
A12: Geothermal | B12: 94.88 | C12: 94.88 | D12: 94.9 | E12: 94.88 | F12: 94.9 | G12: 94.9 | H12: 94.9
A13: Total [MW] | B13: =+SUM(B3:B12) -> 39106.38 | C13: =+SUM(C3:C12) -> 39391.08 | D13: =+SUM(D3:D12) -> 39647.3 | E13: =+SUM(E3:E12) -> 39856.98 | F13: =+SUM(F3:F12) -> 40205.1 | G13: =+SUM(G3:G12) -> 40748.6 | H13: =+SUM(H3:H12) -> 41147.16
A16: Technology | B16: Installed capacity [MW] | C16: %
A17: Hydric | B17: =+C17*$C$25 -> 7556.2 | C17: =+SUM(H3:H4)/$H$13 -> 0.18363843
A18: Natural Gas | B18: =+C18*$C$25 -> 4859.72 | C18: =+H5/$H$13 -> 0.11810584
A19: Coal | B19: =+C19*$C$25 -> 3138.25 | C19: =+H6/$H$13 -> 0.076268933
A20: Diesel | B20: =+C20*$C$25 -> 3105.08 | C20: =+H7/$H$13 -> 0.075462802
A21: Other thermal | B21: =+C21*$C$25 -> 1392.1 | C21: =+H8/$H$13 -> 0.033832226
A22: Eolic | B22: =+C22*$C$25 -> 6837.11 | C22: =+H9/$H$13 -> 0.16616238
A23: Solar (PV +Thermal) | B23: =+C23*$C$25 -> 14163.8 | C23: =+(H10+H11)/$H$13 -> 0.34422303
A24: Geothermal | B24: =+C24*$C$25 -> 94.9 | C24: =+(H12)/$H$13 -> 0.002306356
A25: Total [MW] | B25: =+C25 -> 41147.16 | C25: =+H13 -> 41147.16

Sheet Market Share Estimate
A1: MARKET SHARE ESTIMATE - BESS CHILE
A2: Corrida | B2: 2026-10-01 (Routine mensual) - ver bitacora al final
A3: Universo (base instalada) | B3: ACERA Boletin Estadisticas Agosto-26, Tabla 6: BESS En Operacion = 3.116 MW / 13.522 MWh
A4: Inventario de proyectos | B4: Ministerio de Energia, Reporte de Proyectos agosto 2026 (Tablas 2, 4 y 6) + ACERA ago-26
A5: Atribucion de fabricante | B5: Busqueda web amplia (prensa sectorial, comunicados de fabricantes y de desarrolladores)
A7: ADVERTENCIA METODOLOGICA
A8: 1 | B8: No existe fuente oficial de market share BESS en Chile. Esto es una estimacion, no una cifra dura.
A9: 2 | B9: Regla aplicada: si un proyecto no tiene fabricante identificable con confianza razonable, NO se le asigna uno a ojo;
B10: se excluye del calculo y se lista en la seccion de excluidos.
A11: 3 | B11: La base instalada (En Operacion, criterio ACERA/CEN) se cuenta aparte de lo que esta en pruebas o solo contratado:
B12: un proyecto en pruebas o un contrato firmado todavia no es capacidad instalada y no puede entrar en ese share.
A13: 4 | B13: RESULTADO DE ESTA CORRIDA: la cobertura de atribucion sobre la base instalada sigue siendo demasiado baja para
B14: publicar un % de participacion de mercado. Ver seccion 3. No se publica un porcentaje este mes.
A16: 1. PROYECTOS CON FABRICANTE ATRIBUIDO - BASE INSTALADA (En Operacion)
A17: Proyecto | B17: Propietario / Desarrollador | C17: MW | D17: MWh | E17: Estado | F17: Fabricante / Integrador | G17: Confianza | H17: Fuente
A18: BESS del Desierto | B18: Atlas Renewable Energy | C18: 200 | D18: 800 | E18: En operacion (abr-2025) | F18: Sungrow (PowerTitan) | G18: Alta | H18: Sungrow, caso de estudio utility-scale; energy-storage.news 04-2025
A19: Andes Solar IIb (BESS) | B19: AES Andes | C19: 112 | D19: 560 | E19: En operacion (jul-2023) | F19: Fluence | G19: Alta | H19: energy-storage.news; AES Andes
A20: Virtual Reservoir II - Alfalfal | B20: AES Andes | C20: n/d | D20: 197 | E20: En operacion | F20: Fluence (Gridstack) | G20: Alta | H20: AES Andes / Fluence (Gridstack)
A21: BESS Coya | B21: Engie Chile | C21: 139 | D21: 638 | E21: En operacion (abr-2024) | F21: Sungrow | G21: Media | H21: Prensa sectorial; Engie no publica el fabricante
A23: 2. ATRIBUIDOS QUE NO SON BASE INSTALADA (en pruebas o contrato anunciado) - EXCLUIDOS DEL SHARE
A24: Proyecto | B24: Propietario / Desarrollador | C24: MW | D24: MWh | E24: Estado | F24: Fabricante / Integrador | G24: Confianza | H24: Fuente
A25: BESS Elena Fase I (Oasis de Atacama F6) | B25: Grenergy | C25: 430 | D25: 3010 | E25: En pruebas (Min. Energia ago-26; inaugurado 08-jun-2026) | F25: BYD (MC Cube-T; 6.240 uds / 624 contenedores) | G25: Alta | H25: Grenergy, comunicado 21-05-2025; energy-storage.news 06-2026
A26: Observatorio (PV+BESS) | B26: Verano Energy | C26: 152 | D26: 606 | E26: Contrato anunciado (ago-2026) | F26: Sungrow (PowerTitan 2) | G26: Alta | H26: ess-news.com 12-08-2026
A27: Complejo PV+BESS BHP | B27: BHP | C27: n/d | D27: 960 | E27: Contrato anunciado (jul-2026) | F27: Sungrow | G27: Media | H27: Prensa sectorial 07-2026
A28: Nota | B28: BESS Elena es la primera atribucion Alta a BYD en Chile en esta hoja. NO entra en el share porque el CEN/Min. Energia
B29: lo clasifica En Pruebas a ago-26, no En Operacion. Pasa a la seccion 1 en cuanto ACERA lo reporte en operacion.
A31: 3. COBERTURA DE LA MUESTRA SOBRE LA BASE INSTALADA
A32: Criterio | B32: MW atribuidos | C32: MW universo | D32: Cobertura MW | E32: MWh atribuidos | F32: MWh universo | G32: Cobertura MWh
A33: Solo confianza Alta | B33: 312 | C33: 3116 | D33: 0.10012837 | E33: 1557 | F33: 13522 | G33: 0.11514569
A34: Alta + Media | B34: 451 | C34: 3116 | D34: 0.14473684 | E34: 2195 | F34: 13522 | G34: 0.16232806
A35: Nota | B35: Virtual Reservoir II aporta MWh pero su MW no esta confirmado; no suma a los MW atribuidos.
A36: Nota | B36: La cobertura BAJA respecto de la corrida anterior (11,8% -> 10,0% en MW) sin que se perdiera ninguna atribucion:
B37: el universo ACERA crecio de 2.655 a 3.116 MW y ninguno de los proyectos que entraron en operacion tiene fabricante publico.
A39: 4. CONCLUSION
B40: Con cobertura de 10%-14% de los MW instalados (12%-16% de los MWh), cualquier reparto porcentual entre
B41: fabricantes estaria determinado por los proyectos SIN atribucion, no por los atribuidos. Publicar un share
B42: con esta base seria dar una precision que la metodologia no sostiene, lo que la regla del repo prohibe.
B43: Lectura cualitativa admisible: entre los proyectos con fabricante confirmado publicamente aparecen Sungrow y
B44: Fluence en base instalada, y BYD con el mayor sistema individual del pais (Elena, 3.010 MWh) todavia en pruebas.
B45: NO se debe leer como un ranking de mercado: es lo que se puede ver, no lo que hay. CATL, Tesla, Wartsila, Trina,
...
